<?xml version="1.0" ?>
<robot name="robotiq_hande">
    <link name="hande_base_link">
        <inertial>
            <origin rpy="0 0 0" xyz="0 0 0.04607"/>
            <mass value="0.86387"/>
            <inertia ixx="1017560E-9" ixy="0" ixz="2235E-9" iyy="1028041E-9" iyz="0" izz="489810E-9"/>
        </inertial>
        <visual>
            <origin rpy="0 0 0" xyz="0 0 0"/>
            <geometry>
                <mesh filename="../meshes/hand-e.obj" scale="0.001 0.001 0.001"/>
            </geometry>
        </visual>
        <collision>
            <origin rpy="0 0 0" xyz="0 0 0.052"/>
            <geometry>
                <cylinder radius="0.038" length="0.092" />
            </geometry>
        </collision>
    </link>
    <link name="hande_left_finger">
        <inertial>
            <origin rpy="0 0 0" xyz="0.02262 -0.00759 0.00738"/>
            <mass value="0.03804"/>
            <inertia ixx="13567E-9" ixy="0" ixz="0" iyy="15784E-9" iyz="0" izz="7478E-9"/>
        </inertial>
        <visual>
            <origin rpy="0 0 0" xyz="0 0 0"/>
            <geometry>
                <mesh filename="../meshes/finger_1.obj" scale="0.001 0.001 0.001"/>
            </geometry>
        </visual>
        <collision>
            <origin rpy="0 0 0" xyz="0.028 0 0.024"/>
            <geometry>
                <box size="0.007 0.02 0.045"/>
            </geometry>
        </collision>
    </link>
    <link name="hande_right_finger">
        <inertial>
            <origin rpy="0 0 0" xyz="-0.02262 0.00759 0.00738"/>
            <mass value="0.03804"/>
            <inertia ixx="13567E-9" ixy="0.0" ixz="0.0" iyy="15784E-9" iyz="0.0" izz="7478E-9"/>
        </inertial>
        <visual>
            <origin rpy="0 0 0" xyz="0 0 0"/>
            <geometry>
                <mesh filename="../meshes/finger_2.obj" scale="0.001 0.001 0.001"/>
            </geometry>
        </visual>
        <collision>
            <origin rpy="0 0 0" xyz="-0.028 0 0.024"/>
            <geometry>
                <box size="0.007 0.02 0.045"/>
            </geometry>
        </collision>
    </link>
    <joint name="hande_joint_left_finger" type="prismatic">
        <origin rpy="0 0 0" xyz="0 0 0.099"/>
        <parent link="hande_base_link"/>
        <child link="hande_left_finger"/>
        <axis xyz="-1 0 0"/>
        <limit effort="130" lower="0" upper="0.025" velocity="0.15"/>
    </joint>
    <joint name="hande_joint_right_finger" type="prismatic">
        <origin rpy="0 0 0" xyz="0 0 0.099"/>
        <parent link="hande_base_link"/>
        <child link="hande_right_finger"/>
        <axis xyz="1 0 0"/>
        <limit effort="130" lower="0" upper="0.025" velocity="0.15"/>
    </joint>
    <transmission name="left_finger_transmission">
        <type>transmission_interface/SimpleTransmission</type>
        <joint name="hande_joint_left_finger" />
        <actuator name="motor_left" />
    </transmission>
    <transmission name="right_finger_transmission">
        <type>transmission_interface/SimpleTransmission</type>
        <joint name="hande_joint_right_finger" />
        <actuator name="motor_right" />
    </transmission>
</robot>
